Found using OpenDJ 4.0.0 and OpenDJ 3.5.0 RC1.

Scenario

	install a server
	create a backup

$ ./opendj/bin/backup -h localhost -p 4444 -D "cn=myself" -w password -X -n userRoot -d /tmp/backup2 -I unique-backupid


	try to create a backup with the same backup ID

$ ./opendj/bin/backup -h localhost -p 4444 -D "cn=myself" -w password -X -n userRoot -d /tmp/backup2 -I unique-backupid
-- rc --
returned 1, expected 1
-- stdout --
Backup task 20160628000134628 scheduled to start immediately
[28/Jun/2016:00:01:34 +0200] severity="NOTICE" msgCount=0 msgID=org.opends.messages.backend-413 message="Backup task 20160628000134628 started execution"
[28/Jun/2016:00:01:34 +0200] severity="NOTICE" msgCount=1 msgID=org.opends.messages.tool-280 message="Starting backup for backend userRoot"
[28/Jun/2016:00:01:35 +0200] severity="NOTICE" msgCount=2 msgID=org.opends.messages.utility-321 message="Archived backup file: dj"
[28/Jun/2016:00:01:35 +0200] severity="NOTICE" msgCount=3 msgID=org.opends.messages.utility-321 message="Archived backup file: dj_journal.000000000005"
[28/Jun/2016:00:01:35 +0200] severity="ERROR" msgCount=4 msgID=org.opends.messages.tool-265 message="An error occurred while attempting to back up backend userRoot with the requested configuration:  An error occurred while attempting to update the backup descriptor file /Users/csovant/wks/pyforge/results/20160628-000059/backends_group/tmp/backup2/backup.info with information about the backup: ConfigException: Cannot add a backup with ID unique-backupid to backup directory /Users/csovant/wks/pyforge/results/20160628-000059/backends_group/tmp/backup2 because another backup already exists with that ID (BackupDirectory.java:201 BackupManager.java:560 BackupManager.java:1233 PDBStorage.java:1078 TracedStorage.java:544 BackendImpl.java:800 BackupTask.java:389 BackupTask.java:544 Task.java:965 TaskThread.java:179)"
[28/Jun/2016:00:01:35 +0200] severity="NOTICE" msgCount=5 msgID=org.opends.messages.tool-282 message="The backup process completed with one or more errors"
[28/Jun/2016:00:01:35 +0200] severity="NOTICE" msgCount=6 msgID=org.opends.messages.backend-414 message="Backup task 20160628000134628 finished execution in the state Stopped by error"
Backup task 20160628000134628 did not complete successfully





=> backup failed as expected but we should not print the error as a "ConfigException"